<?xml version="1.0" ?>
<robot name="tm12">

  <link name="base_link">
    <visual>
      <geometry>
        <mesh filename="package://tm_models/meshes/tm12_1300/visual/tm12_base.stl"/>
      </geometry>
      <material name="LightGrey">
        <color rgba="0.5 0.5 0.5 1.0"/>
      </material>
    </visual>
    <collision>
      <geometry>
        <mesh filename="package://tm_models/meshes/tm12_1300/collision/tm12_base_c.STL"/>
      </geometry>
    </collision>
    <inertial>
      <mass value="1.0"/>
      <origin rpy="0 0 0" xyz="0 0 0"/>
      <inertia ixx="0.00110833289" ixy="0.0" ixz="0.0" iyy="0.0018" iyz="0.0" izz="0.00110833289"/>
    </inertial>
  </link>

  <joint name="joint_1" type="revolute">
    <parent link="base_link"/>
    <child link="shoulder_1_link"/>
    <origin rpy="0 0 0" xyz="0 0.1652 0"/>
    <axis xyz="0 1 0"/>
    <limit effort="150.0" lower="-4.71238898038469" upper="4.71238898038469" velocity="3.15"/>
    <dynamics damping="0.0" friction="0.0"/>
  </joint>
  
  <link name="shoulder_1_link">
    <visual>
      <geometry>
        <mesh filename="package://tm_models/meshes/tm12_1300/visual/tm_750w_01.stl"/>
      </geometry>
      <material name="DarkOlive">
        <color rgba="0.3 0.3 0.25 1.0"/>
      </material>
    </visual>
    <collision>
      <geometry>
        <mesh filename="package://tm_models/meshes/tm12_1300/collision/tm_750w_01_c.STL"/>
      </geometry>
    </collision>
    <inertial>
      <mass value="4.5"/>
      <origin rpy="0 0 0" xyz="0 0 0"/>
      <inertia ixx="0.012487495005" ixy="0.0" ixz="0.0" iyy="0.0081" iyz="0.0" izz="0.012487495005"/>
    </inertial>
  </link>

  <joint name="joint_2" type="revolute">
    <parent link="shoulder_1_link"/>
    <child link="arm_1_link"/>
    <origin rpy="0 0 0" xyz="0 0 0.1801"/>
    <axis xyz="0 0 -1"/>
    <limit effort="150.0" lower="-3.141592653589793" upper="3.141592653589793" velocity="3.15"/>
    <dynamics damping="0.0" friction="0.0"/>
  </joint>

  <link name="arm_1_link">
    <visual>
      <geometry>
        <mesh filename="package://tm_models/meshes/tm12_1300/visual/tm12_arm1.stl"/>
      </geometry>
      <material name="DarkOlive">
        <color rgba="0.3 0.3 0.25 1.0"/>
      </material>
    </visual>
    <collision>
      <geometry>
        <mesh filename="package://tm_models/meshes/tm12_1300/collision/tm12_arm1_c.STL"/>
      </geometry>
    </collision>
    <inertial>
      <mass value="11.0"/>
      <origin rpy="0 0 0" xyz="0 0.31805 0"/>
      <inertia ixx="0.38080445684482295" ixy="0.0" ixz="0.0" iyy="0.019799999999999998" iyz="0.0" izz="0.38080445684482295"/>
    </inertial>
  </link>

  <joint name="joint_3" type="revolute">
    <parent link="arm_1_link"/>
    <child link="arm_2_link"/>
    <origin rpy="0 0 0" xyz="0 0.6361 -0.12980000000000003"/>
    <axis xyz="0 0 -1"/>
    <limit effort="150.0" lower="-3.141592653589793" upper="3.141592653589793" velocity="3.15"/>
    <dynamics damping="0.0" friction="0.0"/>
  </joint>

  <link name="arm_2_link">
    <visual>
      <geometry>
        <mesh filename="package://tm_models/meshes/tm12_1300/visual/tm12_arm2.stl"/>
      </geometry>
      <material name="DarkOlive">
        <color rgba="0.3 0.3 0.25 1.0"/>
      </material>
    </visual>
    <collision>
      <geometry>
        <mesh filename="package://tm_models/meshes/tm12_1300/collision/tm12_arm2_c.STL"/>
      </geometry>
    </collision>
    <inertial>
      <mass value="2.5"/>
      <origin rpy="0 0 0" xyz="0 0.27895 0"/>
      <inertia ixx="0.06610985063938249" ixy="0.0" ixz="0.0" iyy="0.0025312499999999996" iyz="0.0" izz="0.06610985063938249"/>
    </inertial>
  </link>

  <joint name="joint_4" type="revolute">
    <parent link="arm_2_link"/>
    <child link="wrist_1_link"/>
    <origin rpy="0 0 0" xyz="0 0.5579 0.106"/>
    <axis xyz="0 0 -1"/>
    <limit effort="150.0" lower="-3.141592653589793" upper="3.141592653589793" velocity="3.15"/>
    <dynamics damping="0.0" friction="0.0"/>
  </joint>

  <link name="wrist_1_link">
    <visual>
      <geometry>
        <mesh filename="package://tm_models/meshes/tm12_1300/visual/tm_100w_01.stl"/>
      </geometry>
      <material name="DarkOlive">
        <color rgba="0.3 0.3 0.25 1.0"/>
      </material>
    </visual>
    <collision>
      <geometry>
        <mesh filename="package://tm_models/meshes/tm12_1300/collision/tm_100w_01_c.STL"/>
      </geometry>
    </collision>
    <inertial>
      <mass value="1.45"/>
      <origin rpy="0 0 0" xyz="0 0 0"/>
      <inertia ixx="0.002474061510375" ixy="0.0" ixz="0.0" iyy="0.001468125" iyz="0.0" izz="0.002474061510375"/>
    </inertial>
  </link>

  <joint name="joint_5" type="revolute">
    <parent link="wrist_1_link"/>
    <child link="wrist_2_link"/>
    <origin rpy="0 0 0" xyz="0 0.106 0"/>
    <axis xyz="0 1 0"/>
    <limit effort="150.0" lower="-3.141592653589793" upper="3.141592653589793" velocity="3.15"/>
    <dynamics damping="0.0" friction="0.0"/>
  </joint>

  <link name="wrist_2_link">
    <visual>
      <geometry>
        <mesh filename="package://tm_models/meshes/tm12_1300/visual/tm_100w_02.stl"/>
      </geometry>
      <material name="DarkOlive">
        <color rgba="0.3 0.3 0.25 1.0"/>
      </material>
    </visual>
    <collision>
      <geometry>
        <mesh filename="package://tm_models/meshes/tm12_1300/collision/tm_100w_02_c.stl"/>
      </geometry>
    </collision>
    <inertial>
      <mass value="1.45"/>
      <origin rpy="0 0 0" xyz="0 0 0"/>
      <inertia ixx="0.002474061510375" ixy="0.0" ixz="0.0" iyy="0.002474061510375" iyz="0.0" izz="0.001468125"/>
    </inertial>
  </link>

  <joint name="joint_6" type="revolute">
    <parent link="wrist_2_link"/>
    <child link="wrist_3_link"/>
    <origin rpy="0 0 0" xyz="0 0 0.11315"/>
    <axis xyz="0 0 1"/>
    <limit effort="150.0" lower="-4.71238898038469" upper="4.71238898038469" velocity="3.15"/>
    <dynamics damping="0.0" friction="0.0"/>
  </joint>

  <link name="wrist_3_link">
    <visual>
      <geometry>
        <mesh filename="package://tm_models/meshes/tm12_1300/visual/tm_ee.stl"/>
      </geometry>
      <material name="LightGrey">
        <color rgba="0.5 0.5 0.5 1.0"/>
      </material>
    </visual>
    <collision>
      <geometry>
        <mesh filename="package://tm_models/meshes/tm12_1300/collision/tm_ee_c.stl"/>
      </geometry>
    </collision>
    <inertial>
      <mass value="0.4"/>
      <origin rpy="0 0 0" xyz="0 0 0"/>
      <inertia ixx="0.000322499871" ixy="0.0" ixz="0.0" iyy="0.000322499871" iyz="0.0" izz="0.000405"/>
    </inertial>
  </link>
  
  <joint name="flange_fixed_joint" type="fixed">
    <parent link="wrist_3_link"/>
    <child link="flange_link"/>
    <origin rpy="0 0 0" xyz="0 0 0"/>
  </joint>
  <link name="flange_link">
    </link>

  <joint name="joint_EOAT" type="fixed">
    <parent link="flange_link"/>
    <child link="EOAT"/>
    <origin xyz="0 0 0" rpy="0 0 0"/>
    <axis xyz="0 0 0"/>
  </joint>

  <link name="EOAT">
    <visual>
      <geometry>
        <mesh filename="package://tmr_description/meshes/gripper/robotiq/2f-85/robotiq_85_gripper.obj"/>
      </geometry>
    </visual>
    <collision>
      <geometry>
        <mesh filename="package://tmr_description/meshes/gripper/robotiq/2f-85/robotiq_85_gripper.stl"/>
      </geometry>
    </collision>
  </link>
  
  <!-- ROS base to TM 'base_link' Coordinates transform -->
  <link name="base"/>
  <joint name="base-base_link" type="fixed">
    <parent link="base"/>
    <child link="base_link"/>
    <origin rpy="1.5707963267948966 0 0" xyz="0 0 0"/>
    <!-- Note: 0.5 * pi -->
  </joint>
  <!-- Frame coincident with all-zeros TCP on TM controller -->
  <link name="tool0"/>
  <joint name="flange_link-tool0" type="fixed">
    <parent link="flange_link"/>
    <child link="tool0"/>
    <origin rpy="0 0 0" xyz="0 0 0"/>
  </joint>
  <link name="world"/>
  <joint name="world_joint" type="fixed">
    <parent link="world"/>
    <child link="base"/>
    <origin rpy="0 0 0" xyz="0 0 0"/>
  </joint>
</robot>
